Workbook
Name FORMGOOGLE: Lembar8!$D$1:$M$805

Sheet Lembar1
A1: DAFTAR PESERTA EBTAQ KORCAB DEMAK, PERIODE ROJAB 1447 H
A3: NO | B3: Nama | C3: JK | D3: Tempat Lahir | E3: Tanggal Lahir | F3: AYAH | G3: IBU | I3: Lembaga
A4: EBTAQ25-03.009 | B4: ALFIAH JULIANTI | C4: Perempuan | D4: DEMAK | E4: 41826 | F4: ACHSANU ROHIM | G4: DEWI KHUSAEMAH | H4: BIO_Images/EBTAQ25-03.009.jpg | I4: BMW - Al Khoiriyah
A5: EBTAQ25-03.010 | B5: NUFIKHO SOFARA KHOIRIYAH | C5: Perempuan | D5: DEMAK | E5: 41995 | F5: ACHMAD SIFULFAZI | G5: LAIKHATUN | H5: BIO_Images/EBTAQ25-03.010.jpg | I5: BMW - Al Khoiriyah
A6: EBTAQ25-03.043 | B6: AZRIL RASYA ABQORY | C6: Laki-laki | D6: DEMAK | E6: 42478 | F6: AHMAD SUPRAPTO | G6: DURROTUN NI'MAH | H6: BIO_Images/EBTAQ25-03.043.jpg | I6: BMW - As-Sa'idiyyah
A7: EBTAQ25-06.008 | B7: IBNU ASSYFA' | C7: Laki-laki | D7: Grobogan | E7: 40488 | F7: EDY SUSANTO | G7: NUR CHAMIDAH | H7: BIO_Images/EBTAQ25-06.008.jpg | I7: BMW - Hidayatul Mubtadiin
A8: EBTAQ25-03.017 | B8: ADILA NISA ARDHANI | C8: Perempuan | D8: Demak | E8: 42646 | F8: KUSMIYANTO | G8: NUR AFIFAH | H8: BIO_Images/EBTAQ25-03.017.jpeg | I8: BMW - Matholiul Falah
A9: EBTAQ25-03.015 | B9: afifa fitiya | C9: Perempuan | D9: demak | E9: 41460 | F9: Arif Wibowo | G9: siti zulaekhah | H9: BIO_Images/EBTAQ25-03.015.jpg | I9: BMW - Matholiul Falah
A10: EBTAQ25-03.007 | B10: Asaa Najma Azzahra | C10: Perempuan | D10: Demak | E10: 42312 | F10: Ahmad Muhajir | G10: Musokhikah | H10: BIO_Images/EBTAQ25-03.007.jpg | I10: BMW - Matholiul Falah
A11: EBTAQ25-03.011 | B11: Indah fadhilah | C11: Perempuan | D11: Demak | E11: 42542 | F11: Nur Rohman | G11: Nazidatul ula | H11: BIO_Images/EBTAQ25-03.011.jpg | I11: BMW - Matholiul Falah
A12: EBTAQ25-03.012 | B12: Indah fadhilah | C12: Perempuan | D12: Demak | E12: 42542 | F12: Nur rohman | G12: Nazidatul ula | H12: BIO_Images/EBTAQ25-03.012.jpg | I12: BMW - Matholiul Falah
A13: EBTAQ25-03.006 | B13: Nur Alifah | C13: Perempuan | D13: Demak | E13: 42318 | F13: Abu rozin | G13: Nur hidayah | H13: BIO_Images/EBTAQ25-03.006.jpg | I13: BMW - Matholiul Falah
A14: EBTAQ25-03.008 | B14: Reva Dwi Rahmadhani | C14: Perempuan | D14: Kudus | E14: 42191 | F14: Nur cipto | G14: Nur ismah | H14: BIO_Images/EBTAQ25-03.008.jpg | I14: BMW - Matholiul Falah
A15: EBTAQ25-03.014 | B15: SANIA INDANA ZULFA | C15: Perempuan | D15: DEMAK | E15: 41600 | F15: MUHSON | G15: ISTIKOMAH | H15: BIO_Images/EBTAQ25-03.014.jpg | I15: BMW - Matholiul Falah
... A176: EBTAQ25-01.148 | B176: MASAYU REGINA RAHMAH | C176: Perempuan | D176: Demak | E176: 41951 | F176: Achmat Munif | G176: Istiqomah | H176: BIO_Images/EBTAQ25-01.148.jpg | I176: SDS IT AZZAHRA DEMAK
A177: EBTAQ25-01.149 | B177: Fadhil Yaqdan Nasrullah | C177: Laki-laki | D177: Demak | E177: 41756 | F177: Faizal Riza | G177: Nur Hasanah | H177: BIO_Images/EBTAQ25-01.149.jpg | I177: Demak - TPQ KH ALJAZERI | K177: Diupdate pada Rabu, 10 Desember 2025 - 07.30 WIB
A178: EBTAQ25-01.150 | B178: ALESYA FATIM GHINARA | C178: Perempuan | D178: DEMAK | E178: 42489 | F178: SURYO HADI WIBOWO | G178: DHUROHMAH | H178: BIO_Images/EBTAQ25-01.150.jpg | I178: SDS IT AZZAHRA DEMAK | K178: Perbaikan atau ralat bisa lapor / konfirmasi ke WA 0896-0898-6635
A179: EBTAQ25-01.151 | B179: ELVIRA ZAHWA ALESHA | C179: Perempuan | D179: KUDUS | E179: 42382 | F179: ROIS ALI SYAHBANA | G179: LILIK MUSTAKFIROH | H179: BIO_Images/EBTAQ25-01.151.jpg | I179: SDS IT AZZAHRA DEMAK
A180: EBTAQ25-01.152 | B180: ALYA APRIANA | C180: Perempuan | D180: DEMAK | E180: 41019 | F180: DIDIK HARYANTO | G180: HARDbANTI SETIYO UTAMI | H180: BIO_Images/EBTAQ25-01.152.jpg | I180: SDS IT AZZAHRA DEMAK
A181: EBTAQ25-01.153 | B181: DANESH RAFASYA | C181: Perempuan | D181: DEMAK | E181: 42161 | F181: CIPTO LEGOWO | G181: ERNA TRI PUJIASTUTI | H181: BIO_Images/EBTAQ25-01.153.jpg | I181: SDS IT AZZAHRA DEMAK
A182: EBTAQ25-01.154 | B182: NABILA INDAH PERMATA | C182: Perempuan | D182: DEMAK | E182: 41601 | F182: SUBARI | G182: NUR KHASANAH | H182: BIO_Images/EBTAQ25-01.154.jpg | I182: SDS IT AZZAHRA DEMAK
A183: EBTAQ25-01.155 | B183: HAMDA SAKHIA ABDILLAH | C183: Perempuan | D183: DEMAK | E183: 41616 | F183: RIF'AAN ABDILLAH | G183: NUR HASANAH | H183: BIO_Images/EBTAQ25-01.155.jpg | I183: SDS IT AZZAHRA DEMAK
A184: EBTAQ25-01.156 | B184: ARDILA SEPTIANI | C184: Perempuan | D184: Demak | E184: 41889 | F184: Drajad sigit marsinggih | G184: Nur faida | H184: BIO_Images/EBTAQ25-01.156.jpg | I184: Demak - TPQ KH ALJAZERI
A185: EBTAQ25-01.157 | B185: Shofia naila saadah | C185: Perempuan | D185: Demak | E185: 42591 | F185: Chairul Anam | G185: Khoirotun Nisa | H185: BIO_Images/EBTAQ25-01.157.jpg | I185: Demak - TPQ KH ALJAZERI
A186: EBTAQ25-01.158 | B186: Atika Zahra Latifa | C186: Perempuan | D186: demak | E186: 41776 | F186: ABDUL HADI | G186: TIKA IKHWAL MARYANA | H186: BIO_Images/EBTAQ25-01.158.jpg | I186: Demak - TPQ KH ALJAZERI
A187: EBTAQ25-01.159 | B187: Atika zahra latifa | C187: Perempuan | D187: Demak | E187: 41776 | F187: Abdul hadi | G187: Tika ikhwal maryana | H187: BIO_Images/EBTAQ25-01.159.jpg | I187: Demak - TPQ KH ALJAZERI
A188: EBTAQ25-01.160 | B188: Naella Putri Olivia | C188: Perempuan | D188: Semarang | E188: 41903 | F188: Muhammad muntoha | G188: Upik Nilawati | H188: BIO_Images/EBTAQ25-01.160.jpg | I188: Demak - TPQ KH ALJAZERI
A189: EBTAQ25-01.161 | B189: JIHAN AZZAHRA | C189: Perempuan | D189: DEMAK | E189: 41702 | F189: IPUNG TRI YUWANTORO | G189: RAMAYANTI | H189: BIO_Images/EBTAQ25-01.161.jpg | I189: Demak - TPQ KH ALJAZERI
A190: EBTAQ25-01.162 | B190: Murni Asih Ardianti | C190: Perempuan | D190: Demak, Jawa tengah | E190: 41644 | F190: Zaenal Sodikin | G190: Dewi Ratnawati | H190: BIO_Images/EBTAQ25-01.162.jpg | I190: Demak - TPQ KH ALJAZERI
... A411: EBTAQ25-03.077 | B411: FIA LARASATI | C411: Perempuan | D411: Demak | E411: 41814 | F411: MIFTA KHARIS | G411: SHOFIYATI | H411: BIO_Images/EBTAQ25-03.077.jpg | I411: BMW - Yanbu'ul Qur'an
A412: EBTAQ25-01.310 | B412: ADRIAN PRADIPTA WIJAYA | C412: Laki-laki | D412: 42287 | E412: 42287 | F412: DANANG HARYANTO | G412: NIKMATUL INAYAH | H412: BIO_Images/EBTAQ25-01.310.jpg | I412: Demak - TPQ ROUDHOTUL JANNAH
A413: EBTAQ25-03.078 | B413: KIRANA 'AROFATUSYALISAH | C413: Perempuan | D413: DEMAK | E413: 41909 | F413: MUAYADI | G413: MUDAYANAH | H413: BIO_Images/EBTAQ25-03.078.jpg | I413: BMW - As-Sa'idiyyah
A414: EBTAQ25-03.079 | B414: SAFEEA DAMAYANTI | C414: Perempuan | D414: DEMAK | E414: 42487 | F414: IMAM SAFI'I | G414: NIKMATUL IFAH | H414: BIO_Images/EBTAQ25-03.079.jpg | I414: BMW - As-Sa'idiyyah
A415: EBTAQ25-03.080 | B415: TIKTA ZULIYANTI AYUNINGTYAS | C415: Perempuan | D415: DEMAK | E415: 41839 | F415: MUHSININ | G415: NANIK AINISAH | H415: BIO_Images/EBTAQ25-03.080.jpg | I415: BMW - As-Sa'idiyyah
A416: EBTAQ25-03.081 | B416: AZKIA NAJIHA KIRANA | C416: Perempuan | D416: DEMAK | E416: 42173 | F416: HARYANTO | G416: MUSLIKHATUL HIDAYAH | H416: BIO_Images/EBTAQ25-03.081.jpg | I416: BMW - As-Sa'idiyyah
A417: EBTAQ25-03.082 | B417: Rahma Ardi Ramadhani | C417: Perempuan | D417: Demak | E417: 41824 | F417: Suhardi | G417: Rofiah | H417: BIO_Images/EBTAQ25-03.082.jpg | I417: BMW - Yanbu'ul Qur'an
A418: EBTAQ25-03.083 | B418: FIA LARASSATI | C418: Perempuan | D418: Demak | E418: 41814 | F418: MIFTA KHARIS | G418: SHOFIYATI | H418: BIO_Images/EBTAQ25-03.083.jpg | I418: BMW - Yanbu'ul Qur'an
A419: EBTAQ25-03.083 | B419: Rahma Ardi Ramadhani | C419: Perempuan | D419: Demak | E419: 41824 | F419: Suhardi | G419: Rofiah | H419: BIO_Images/EBTAQ25-03.083.jpg | I419: BMW - Yanbu'ul Qur'an
A420: EBTAQ25-03.083 | B420: Rahma Ardi Ramadhani | C420: Perempuan | D420: Demak | E420: 41824 | F420: Suhardi | G420: Rofiah | H420: BIO_Images/EBTAQ25-03.083.jpg | I420: BMW - Yanbu'ul Qur'an
A421: EBTAQ25-03.084 | B421: RAHMA ARDI RAMADHANI | C421: Perempuan | D421: Demak | E421: 41824 | F421: Suhardi | G421: Rofiah | H421: BIO_Images/EBTAQ25-03.084.jpg | I421: BMW - Yanbu'ul Qur'an
...

Sheet Lembar4
A1: LEMBAGA | B1: ID | C1: NAMA | D1: JK | E1: TL | F1: TL | G1: BIN | H1: BINTI
A2: BMW - Al Khoiriyah | B2: EBTAQ25.03.009 | C2: ALFIAH JULIANTI | D2: Perempuan | E2: DEMAK | F2: 41826 | G2: ACHSANU ROHIM | H2: DEWI KHUSAEMAH | I2: BIO_Images/EBTAQ25-03.009.jpg | J2: =VLOOKUP(C2,FORMGOOGLE,7,FALSE) -> https://drive.google.com/open?id=1psFhggJNjW0Q06-AS_03545oWNwba2eD
A3: BMW - Al Khoiriyah | B3: EBTAQ25.03.010 | C3: NUFIKHO SOFARA KHOIRIYAH | D3: Perempuan | E3: DEMAK | F3: 41995 | G3: ACHMAD SIFULFAZI | H3: LAIKHATUN | I3: BIO_Images/EBTAQ25-03.010.jpg | J3: =VLOOKUP(C3,FORMGOOGLE,7,FALSE) -> https://drive.google.com/open?id=1s3LFdyMeqFalnRmaui5QMwT40phv-BJm
A4: BMW - As-Sa'idiyyah | B4: EBTAQ25.03.072 | C4: AHMAD FERI AKBAR | D4: Laki-laki | E4: DEMAK | F4: 42047 | G4: NUR ROCHIM | H4: FARIDHOTUL CHASANAH | I4: BIO_Images/EBTAQ25-03.072.jpg | J4: =VLOOKUP(C4,FORMGOOGLE,7,FALSE) -> https://drive.google.com/open?id=1SDaqqz8FjmLECG_PwZoqNVbdvUH_ztDm
A5: BMW - As-Sa'idiyyah | B5: EBTAQ25.03.081 | C5: AZKIA NAJIHA KIRANA | D5: Perempuan | E5: DEMAK | F5: 42173 | G5: HARYANTO | H5: MUSLIKHATUL HIDAYAH | I5: BIO_Images/EBTAQ25-03.081.jpg | J5: =VLOOKUP(C5,FORMGOOGLE,7,FALSE) -> https://drive.google.com/open?id=1W8hDgK5sI05j5MzPA1OqlLedyPVaqiKk
A6: BMW - As-Sa'idiyyah | B6: EBTAQ25.03.043 | C6: AZRIL RASYA ABQORY | D6: Laki-laki | E6: DEMAK | F6: 42478 | G6: AHMAD SUPRAPTO | H6: DURROTUN NI'MAH | I6: BIO_Images/EBTAQ25-03.043.jpg | J6: =VLOOKUP(C6,FORMGOOGLE,7,FALSE) -> https://drive.google.com/open?id=1ToQh-zRpk_WlpucmnutVYAyqHT-2h9kZ
A7: BMW - As-Sa'idiyyah | B7: EBTAQ25.03.074 | C7: BILQIS FAIHA RIFDA | D7: Perempuan | E7: DEMAK | F7: 41991 | G7: MUSRIAN | H7: SUYATI | I7: BIO_Images/EBTAQ25-03.074.jpg | J7: =VLOOKUP(C7,FORMGOOGLE,7,FALSE) -> https://drive.google.com/open?id=1u4o_UvKvF0x01zSTBUeEJEoT5rrIyOlJ
A8: BMW - As-Sa'idiyyah | B8: EBTAQ25.03.075 | C8: FARISYA FINATUL AGUSTINA | D8: Perempuan | E8: DEMAK | F8: 41868 | G8: MUHAMMAD ARIS | H8: NAFISSATUN NAJIKHAH | I8: BIO_Images/EBTAQ25-03.075.jpg | J8: =VLOOKUP(C8,FORMGOOGLE,7,FALSE) -> https://drive.google.com/open?id=1r8lhsDsZB1mTBwxbps_rfzhzJYlY8199
A9: BMW - As-Sa'idiyyah | B9: EBTAQ25.03.076 | C9: INAYATUR ROHMAH | D9: Perempuan | E9: DEMAK | F9: 41913 | G9: HASAN BISRI | H9: NUR FAIZAH | I9: BIO_Images/EBTAQ25-03.076.jpg | J9: =VLOOKUP(C9,FORMGOOGLE,7,FALSE) -> https://drive.google.com/open?id=1P9GETMCZuDRzZgKdSxk5zWGFoSP12QmI
A10: BMW - As-Sa'idiyyah | B10: EBTAQ25.03.078 | C10: KIRANA 'AROFATUSYALISAH | D10: Perempuan | E10: DEMAK | F10: 41909 | G10: MUAYADI | H10: MUDAYANAH | I10: BIO_Images/EBTAQ25-03.078.jpg | J10: =VLOOKUP(C10,FORMGOOGLE,7,FALSE) -> https://drive.google.com/open?id=1LQ3SXlZFH3Kriut1xpptlTEswZCHq4A0
A11: BMW - As-Sa'idiyyah | B11: EBTAQ25.03.071 | C11: MUHAMMAD FAHMI AMMAR | D11: Laki-laki | E11: DEMAK | F11: 41758 | G11: ABU HASAN | H11: MUYASAROH | I11: BIO_Images/EBTAQ25-03.071.jpg | J11: =VLOOKUP(C11,FORMGOOGLE,7,FALSE) -> https://drive.google.com/open?id=1YxamQuGn0RJyCNFoEPZglloBjiyHVl6i
A12: BMW - As-Sa'idiyyah | B12: EBTAQ25.03.079 | C12: SAFEEA DAMAYANTI | D12: Perempuan | E12: DEMAK | F12: 42487 | G12: IMAM SAFI'I | H12: NIKMATUL IFAH | I12: BIO_Images/EBTAQ25-03.079.jpg | J12: =VLOOKUP(C12,FORMGOOGLE,7,FALSE) -> https://drive.google.com/open?id=1YWO7rWiFVnhn0tRv8W3X-a00y4gtsNI4
A13: BMW - As-Sa'idiyyah | B13: EBTAQ25.03.080 | C13: TIKTA ZULIYANTI AYUNINGTYAS | D13: Perempuan | E13: DEMAK | F13: 41839 | G13: MUHSININ | H13: NANIK AINISAH | I13: BIO_Images/EBTAQ25-03.080.jpg | J13: =VLOOKUP(C13,FORMGOOGLE,7,FALSE) -> https://drive.google.com/open?id=1Us9NmwNeMDot6NKD1jcBov-79KpCK0LS
... A202: Demak - TPQ ALHUSNA (MI) | B202: EBTAQ25-01.257 | C202: Muhammad Fairuz Dzulfadhly | D202: Laki-laki | E202: Demak | F202: 41925 | G202: Imamul Muttaqin | H202: Nasikhah | I202: BIO_Images/EBTAQ25-01.257.jpg | J202: =VLOOKUP(C202,FORMGOOGLE,7,FALSE) -> https://drive.google.com/open?id=1VnTLp2RssADWEGe-TRFaZFimwy_pyA55
A203: Demak - TPQ ALHUSNA (MI) | B203: EBTAQ25-05.043 | C203: MUHAMMAD KAFA ASSARIF | D203: Laki-laki | E203: DEMAK | F203: 42192 | G203: ZUHARIS SUHARIMAN | H203: AFIDATUL LAYINAH | I203: #N/A | J203: =VLOOKUP(C203,FORMGOOGLE,7,FALSE) -> https://drive.google.com/open?id=1LfamwvMgHMFzh1C4F4yD_mxU_rASbBj8
A204: Demak - TPQ ALHUSNA (MI) | B204: EBTAQ25-01.277 | C204: Muhammad Nazzala Furqon Aly | D204: Laki-laki | E204: Demak | F204: 42543 | G204: Ali Chamdan | H204: Fatimah | I204: BIO_Images/EBTAQ25-01.277.jpg | J204: =VLOOKUP(C204,FORMGOOGLE,7,FALSE) -> https://drive.google.com/open?id=1R0xsZ3JB5WgoYfr2w3W-xVpxfuR93nW8
A205: Demak - TPQ ALHUSNA (MI) | B205: EBTAQ25-01.261 | C205: Muhammad Syakir Rizqullah | D205: Laki-laki | E205: Sidoarjo | F205: 42283 | G205: Imamul Muttaqin | H205: Nasikhah | I205: BIO_Images/EBTAQ25-01.261.jpg | J205: =VLOOKUP(C205,FORMGOOGLE,7,FALSE) -> https://drive.google.com/open?id=1nXHMHWvyt9YmIDP8GFGOndQ_eu4F6tkT
A206: Demak - TPQ ALHUSNA (MI) | B206: EBTAQ25-01.287 | C206: Muhammad Vallentino Kevin El Fasya | D206: Laki-laki | E206: Demak | F206: 41925 | G206: Heri Kiswanto | H206: Ana Zulfa Rahmawati | I206: BIO_Images/EBTAQ25-01.287.jpeg | J206: =VLOOKUP(C206,FORMGOOGLE,7,FALSE) -> https://drive.google.com/open?id=1nYgtEnvBc-2oafr89_vMw6tvhgcnSXE8
A207: Demak - TPQ ALHUSNA (MI) | B207: EBTAQ25-01.275 | C207: Muhammad Yasiin | D207: Laki-laki | E207: DEMAK | F207: 42299 | G207: Suhartono | H207: Tutik Subiyanti | I207: BIO_Images/EBTAQ25-01.275.jpg | J207: =VLOOKUP(C207,FORMGOOGLE,7,FALSE) -> https://drive.google.com/open?id=1GAroFSRp1Ii272XDhixMhAwsta8qjBNM
A208: Demak - TPQ ALHUSNA (MI) | B208: EBTAQ25-01.293 | C208: Musyafa nur jati | D208: Laki-laki | E208: Demak | F208: 42170 | G208: Nadliron | H208: Winarsih | I208: BIO_Images/EBTAQ25-01.293.jpg | J208: =VLOOKUP(C208,FORMGOOGLE,7,FALSE) -> https://drive.google.com/open?id=1AkUa0BS0NAaiUOwB3Xgw-QEgpxLnD-nD
A209: Demak - TPQ ALHUSNA (MI) | B209: EBTAQ25-01.250 | C209: Nabillah Damara Najmy Kallani | D209: Perempuan | E209: Demak | F209: 42733 | G209: Achmadi | H209: Dwi Puji Asmorodewi | I209: BIO_Images/EBTAQ25-01.250.jpg | J209: =VLOOKUP(C209,FORMGOOGLE,7,FALSE) -> https://drive.google.com/open?id=1yefzqLQFpzpNv6RhFf9fm5kZStIAO1S4
A210: Demak - TPQ ALHUSNA (MI) | B210: EBTAQ25-01.256 | C210: Nadine Aulia Firdaus | D210: Perempuan | E210: Demak | F210: 42272 | G210: Ali Firdaus | H210: Mujiyatun | I210: BIO_Images/EBTAQ25-01.256.jpg | J210: =VLOOKUP(C210,FORMGOOGLE,7,FALSE) -> https://drive.google.com/open?id=1FMCv-OTNjtD4cu_4XJfLIvrcqilIeQyx
A211: Demak - TPQ ALHUSNA (MI) | B211: EBTAQ25-01.296 | C211: Nasyahila ufaira marwa | D211: Perempuan | E211: Demak | F211: 42281 | G211: Nur khamim | H211: Kholis wati | I211: BIO_Images/EBTAQ25-01.296.jpg | J211: =VLOOKUP(C211,FORMGOOGLE,7,FALSE) -> https://drive.google.com/open?id=1koccTZvq0-DWYxDEU4pijkrtdAMdaxTK
A212: Demak - TPQ ALHUSNA (MI) | B212: EBTAQ25-01.276 | C212: NAZZAHRA FLORENZIA HAQQI | D212: Perempuan | E212: DEMAK | F212: 42553 | G212: BARKAH ULHAQ ARI WIDODO | H212: CITRAYOGI CAHYO SUNDARI | I212: BIO_Images/EBTAQ25-01.276.jpg | J212: =VLOOKUP(C212,FORMGOOGLE,7,FALSE) -> https://drive.google.com/open?id=18vn_P_zdAUY6xw7TO7HDwD-3BonY26NF
A213: Demak - TPQ ALHUSNA (MI) | B213: EBTAQ25-01.252 | C213: Rakha Alhafeezy Putra Setiawan | D213: Laki-laki | E213: Demak | F213: 41907 | G213: Andika Yoan Setiawan | H213: Endang Setyowati | I213: BIO_Images/EBTAQ25-01.252.jpg | J213: =VLOOKUP(C213,FORMGOOGLE,7,FALSE) -> https://drive.google.com/open?id=1iGR_E4Z2vsNTTwrRZsBbdEgDmyD4JhcB
A214: Demak - TPQ ALHUSNA (MI) | B214: EBTAQ25-01.268 | C214: RIFKI RIDHO | D214: Laki-laki | E214: Demak | F214: 42307 | G214: MUHIBBIN | H214: SUMIYATI | I214: BIO_Images/EBTAQ25-01.268.jpg | J214: =VLOOKUP(C214,FORMGOOGLE,7,FALSE) -> https://drive.google.com/open?id=1VrlskstDc4qBThiFEYUpZRoXn_aw3a6h
A215: Demak - TPQ ALHUSNA (MI) | B215: EBTAQ25-01.264 | C215: Shakila Adzkiya Sakhi Hayza | D215: Perempuan | E215: Semarang | F215: 42929 | G215: M. Satria Indra Purnama Sakti | H215: Nur Chamidah | I215: BIO_Images/EBTAQ25-01.264.jpg | J215: =VLOOKUP(C215,FORMGOOGLE,7,FALSE) -> https://drive.google.com/open?id=1C4S2RNHsMXPKdYbhVQIjmJw_8Dhoit7i
... A317: DEMAK - TPQ Raudlatul Muta'allimin | B317: EBTAQ25-01.147 | C317: Muhammad khoirul azam | D317: Laki-laki | E317: Demak | F317: 43448 | G317: Subakir | H317: Kusrini | I317: BIO_Images/EBTAQ25-01.147.jpg | J317: =VLOOKUP(C317,FORMGOOGLE,7,FALSE) -> https://drive.google.com/open?id=1UTslcn3OyPqC4-G7Ke2WjORM43S3M58-
A318: Demak - TPQ ROUDHOTUL JANNAH | B318: EBTAQ25-01.310 | C318: ADRIAN PRADIPTA WIJAYA | D318: Laki-laki | E318: 42287 | F318: 42287 | G318: DANANG HARYANTO | H318: NIKMATUL INAYAH | I318: BIO_Images/EBTAQ25-01.310.jpg | J318: =VLOOKUP(C318,FORMGOOGLE,7,FALSE) -> https://drive.google.com/open?id=1R65QIAANHQCxsGdRzrm7tyiIfSY0fuKB
A319: Demak - TPQ SULAMUNNAJAH | B319: EBTAQ25-01.289 | C319: Alayya Nahda Rafanda | D319: Perempuan | E319: Demak | F319: 42272 | G319: Sumber Kusnadi | H319: IRA SOFIANA | I319: BIO_Images/EBTAQ25-01.289.jpeg | J319: =VLOOKUP(C319,FORMGOOGLE,7,FALSE) -> https://drive.google.com/open?id=1iFjITDLXK7VFyEP5_NpZJySSTlYKAZl5
A320: Demak - TPQ SULAMUNNAJAH | B320: EBTAQ25-01.299 | C320: RHEA AINAYA SAPUTRA | D320: Perempuan | E320: Demak | F320: 42563 | G320: Lilik Dwi Saputro | H320: ANIK ANDRIANINGRUM | I320: BIO_Images/EBTAQ25-01.299.jpeg | J320: =VLOOKUP(C320,FORMGOOGLE,7,FALSE) -> https://drive.google.com/open?id=1YZ9e9PPnxhhRTdxq8SbsoqfdkKubDF4l
A321: Demak - TPQ SULAMUNNAJAH | B321: EBTAQ25-01.301 | C321: Wimala Nuriel Sefti Elysia | D321: Perempuan | E321: Klaten | F321: 42614 | G321: Iswanto | H321: Nur Kayati | I321: BIO_Images/EBTAQ25-01.301.jpeg | J321: =VLOOKUP(C321,FORMGOOGLE,7,FALSE) -> https://drive.google.com/open?id=1zydE7SvMfDEOZmT6HIWXthmyDF5c80Zd
A322: Dewoka - Assalamah | B322: EBTAQ25-03.133 | C322: Ayunda Bella Orlin | D322: Perempuan | E322: Demak | F322: 42239 | G322: Mokhamad mustaqim | H322: Mutriah | I322: BIO_Images/EBTAQ25-03.133.Foto.232349.jpg | J322: =VLOOKUP(C322,FORMGOOGLE,7,FALSE) -> https://drive.google.com/open?id=1D0xtIGib75JpcOeL7shhVxICaRjPgXTk
A323: Dewoka - Assalamah | B323: EBTAQ25-03.132 | C323: KAISA FARZANA ASFIA | D323: Perempuan | E323: DEMAK | F323: 42748 | G323: CHOLIQUL AHSAN | H323: DURROTUN NASHIHAH | I323: BIO_Images/EBTAQ25-03.132.Foto.232524.jpg | J323: =VLOOKUP(C323,FORMGOOGLE,7,FALSE) -> https://drive.google.com/open?id=1LobfRd9C-d4R6m55FLZ2DiaRknSg_JLN
A324: Dewoka - Assalamah | B324: EBTAQ25-03.131 | C324: RIZKY KHOIRUL KHAMDANI | D324: Laki-laki | E324: DEMAK | F324: 42087 | G324: MOH KHOIRI | H324: DESI KARTIKA SARI | I324: BIO_Images/EBTAQ25-03.131.Foto.232620.jpg | J324: =VLOOKUP(C324,FORMGOOGLE,7,FALSE) -> https://drive.google.com/open?id=1rsZs2C51Q-gaY6LItyqBK7AzKezP-9Hl
A325: Dewoka - Assalamah | B325: EBTAQ25-03.129 | C325: SISCA OLIVIA | D325: Perempuan | E325: DEMAK | F325: 41545 | G325: MUSTHOFA | H325: MUNAFIAH | I325: BIO_Images/EBTAQ25-03.129.Foto.232701.jpg | J325: =VLOOKUP(C325,FORMGOOGLE,7,FALSE) -> https://drive.google.com/open?id=1Ot7nzUstYzC486mZVkShIqToDW-UWy6u
A326: Dewoka - Bustanul Muta'allimin | B326: EBTAQ25-02.062 | C326: Bella Citra Mahardika | D326: Perempuan | E326: Demak | F326: 42138 | G326: Joko Susilo | H326: Ari Praptiningsih | I326: BIO_Images/EBTAQ25-02.062.jpg | J326: =VLOOKUP(C326,FORMGOOGLE,7,FALSE) -> https://drive.google.com/open?id=1LzXhyAyvSeWqcJfrTQGqMHQekdKMZ3PF
A327: Dewoka - Bustanul Muta'allimin | B327: EBTAQ25-02.061 | C327: Dwi Arsya Azahra | D327: Perempuan | E327: Demak | F327: 42821 | G327: Amin Sugiharso | H327: Irfatul Uliyah | I327: BIO_Images/EBTAQ25-02.061.jpg | J327: =VLOOKUP(C327,FORMGOOGLE,7,FALSE) -> https://drive.google.com/open?id=1Gjjfy9IKk9ZYBnxBghw-8ekzayts5zAa
A328: Dewoka - Bustanul Muta'allimin | B328: EBTAQ25-02.063 | C328: Fitri Nurul Nafisah | D328: Perempuan | E328: Demak | F328: 42558 | G328: - | H328: Titik Asmorowati | I328: BIO_Images/EBTAQ25-02.063.jpg | J328: =VLOOKUP(C328,FORMGOOGLE,7,FALSE) -> https://drive.google.com/open?id=1iKHQrLbf6cSREyxW8CLecTg2jawcUwjO
A329: Dewoka - Bustanul Muta'allimin | B329: EBTAQ25-02.059 | C329: Jovan Alaric Wahyu Adijaya | D329: Laki-laki | E329: Sukoharjo | F329: 42222 | G329: Slamet Widodo | H329: Hartini Wati | I329: BIO_Images/EBTAQ25-02.059.jpg | J329: =VLOOKUP(C329,FORMGOOGLE,7,FALSE) -> https://drive.google.com/open?id=1rZO_IojWByuDfKb-PeU59ml9rlSG-BW9
...

Sheet Lembar8
A1: 45967.632 | B1: Mranggen | C1: Mranggen - Futuhiyyah | D1: SITI NUR SALSABILA | E1: Kendal | F1: 40885 | G1: SHOLIKHIN | H1: NGASTI'AH | I1: Perempuan | J1: https://drive.google.com/open?id=1mrEM8U6G0fnxB_WTM_uGprNxAl7eOq0e | K1: fatimatuzzahra828@gmail.com | L1: EBTAQ25-06.001
A2: 45968.45 | B2: Demak | C2: Demak - TPQ KH ALJAZERI | D2: WAKHIDATUN NAILIS SA'ADAH | E2: Demak | F2: 42501 | G2: MAD SOLEH | H2: SITI KHOLIFAH | I2: Perempuan | J2: https://drive.google.com/open?id=1CxbLWtvE5o0cP9rqTU94xgy6vevWYehK | K2: nikmaturrosyidah4@gmail.com | L2: EBTAQ25-01.111 | M2: https://drive.google.com/file/d/149ZcJWZKRBGgnZcEt-5zAFELzAWTeuhf/view?usp=drivesdk
A3: 45968.495 | B3: Demak | C3: Demak - TPQ KH ALJAZERI | D3: Atika Zahra Latifa | E3: Demak | F3: 41776 | G3: Abdul Hadi | H3: Tika Ikhwal Maryana | I3: Perempuan | J3: https://drive.google.com/open?id=1-nHm9EXUgpOrxGSEEER_gd2MzcM0-AUU | K3: safarohnizam@gmail.com | L3: EBTAQ25-01.112 | M3: https://drive.google.com/file/d/17FDEWneIX3pFjiXjVZWejPQ5zwFH3zq7/view?usp=drivesdk
A4: 45969.375 | B4: Demak | C4: Demak - TPQ ALHADID | D4: Keisha Laila Fajrina | E4: Demak | F4: 42488 | G4: Mohamad Fatkhan | H4: Sukinah | I4: Perempuan | J4: https://drive.google.com/open?id=1f5SwUGtvDG6QgH4U3gKJlQTxwe1MwDIH | K4: hikmatulishaq@gmail.com | L4: EBTAQ25-01.113 | M4: https://drive.google.com/file/d/1S1EnzUcSIlncCOXIW-y-UYZySpxnWtrK/view?usp=drivesdk
A5: 45969.701 | B5: Demak | C5: Demak - TPQ ALHADID | D5: ADELIA KHAIRA WILDA | E5: DEMAK | F5: 42037 | G5: ZAENAL ABIDIN | H5: JIJIN TURIASIH | I5: Perempuan | J5: https://drive.google.com/open?id=1x0WjMDp1vEONPYIFlWgEEhmV92TyO6i0 | K5: nakhilajihan@gmail.com | L5: EBTAQ25-01.114 | M5: https://drive.google.com/file/d/1EvjlRBAVrIAOWUp1uoIG7LEz7ATejl9R/view?usp=drivesdk
A6: 45969.707 | B6: Demak | C6: Demak - TPQ ALHADID | D6: Annisa faiha | E6: Demak | F6: 42841 | G6: Kholil Bisri | H6: Himmatul Ulliya | I6: Perempuan | J6: https://drive.google.com/open?id=17le2Igs59p_HTSCsAR3GNNJt2RIMSDCY | K6: faihaannisa632@gmail.com | L6: EBTAQ25-01.115 | M6: https://drive.google.com/file/d/1XjXJtEPl3B4Z5iGDIg75rMCNXz0i-1_f/view?usp=drivesdk
A7: 45969.71 | B7: Demak | C7: Demak - TPQ ALHADID | D7: octafia ayu rahmawati | E7: Demak | F7: 42307 | G7: purwadi | H7: saudah | I7: Perempuan | J7: https://drive.google.com/open?id=11JLbasjtEy0YNiuuHAGDR05kzL8r2mTs | K7: khusna8765@gmail.com | L7: EBTAQ25-01.116 | M7: https://drive.google.com/file/d/1sYSdtjmuBXfAU8eS9sDn2m_a-iJScwgf/view?usp=drivesdk
A8: 45969.713 | B8: Demak | C8: Demak - TPQ ALHADID | D8: AQILA QURROTU A'YUN | E8: Demak | F8: 42577 | G8: Sucipto | H8: Kholisoh | I8: Perempuan | J8: https://drive.google.com/open?id=1rW0U4BxDjbyOl2mhyPLhvdRdedM758eF | K8: suciptokarangmlati@gmail.com | L8: EBTAQ25-01.117 | M8: https://drive.google.com/file/d/1lud1iW1ZfaSG2vQU33r5nidI79TTuo11/view?usp=drivesdk
A9: 45969.714 | B9: Demak | C9: Demak - TPQ ALHADID | D9: Nurul Fauziyah Ramadhani | E9: Demak | F9: 41482 | G9: Muhidin | H9: Sri kumaidah | I9: Perempuan | J9: https://drive.google.com/open?id=1JNVvb5MHz_uR3Se5WpFia029sUNc5CvC | K9: fikriyahhd@gmail.com | L9: EBTAQ25-01.118 | M9: https://drive.google.com/file/d/1kd4F2IwGWQ2a0pKywjKyKjQDpOyfseEK/view?usp=drivesdk
A10: 45969.722 | B10: Demak | C10: Demak - TPQ ALHADID | D10: Aisya Faiha Maulidya | E10: Demak | F10: 42729 | G10: Masri | H10: Kasiroh | I10: Perempuan | J10: https://drive.google.com/open?id=1TWXX2Dc3Rz4kjWJ-tCJAgX26qkrP6gvh | K10: mawarmelati1503@gmail.com | L10: EBTAQ25-01.119 | M10: https://drive.google.com/file/d/15fXGhFlhRT0fllOpTzons26Mhuoo_NQz/view?usp=drivesdk
A11: 45972.006 | B11: Mranggen | C11: Mranggen - Darul qur'an | D11: AQILA RAISA AILANI MA'ARIF | E11: Semarang | F11: 41853 | G11: Khusnul Ma'arif | H11: Nur Khoiroh Wijayanti | I11: Perempuan | J11: https://drive.google.com/open?id=1kV7426-pZepQwruh-h4gakwsSJ1VIWc1 | K11: rmaghfiroh881@gmail.com | L11: EBTAQ25-06.002 | M11: https://drive.google.com/file/d/1gt_POAXQ21jIiShA8tSKzkmzmGd0Kr9g/view?usp=drivesdk
A12: 45972.036 | B12: Mranggen | C12: Mranggen - Darul qur'an | D12: Ahmad Fakhryl Mubarok | E12: Demak | F12: 41787 | G12: Anton Husni Mubarok | H12: Akmalia | I12: Laki-laki | J12: https://drive.google.com/open?id=1w25YpuRXIefDgcDRiGW1VWfusl3lFqcR | K12: zakiyazaa231@gmail.com | L12: EBTAQ25-06.003 | M12: https://drive.google.com/file/d/1Z8VAly-FHrt4-JIjrjnOWfb91tQRMS3H/view?usp=drivesdk
A13: 45972.041 | B13: Mranggen | C13: Mranggen - Darul qur'an | D13: Ayyash | E13: Semarang | F13: 42271 | G13: Dian Hadi Saputra | H13: May Kurniawati | I13: Laki-laki | J13: https://drive.google.com/open?id=1jOANmbzmyYjUM6tdjRiWi4fMqMz5vD3g | K13: dinakhulala12@gmail.com | L13: EBTAQ25-06.004 | M13: https://drive.google.com/file/d/18qA0XYpW8znmpl-jwf8kLxpd3vcgDhl7/view?usp=drivesdk
... A36: 45994.96 | B36: Karbon | C36: Karbon - TPQ MASITHOH 8 | D36: Shakila Dzahin Nicky Azzahra | E36: Demak | F36: 42604 | G36: Nicky Yulianto | H36: Mimin Afita Sari | I36: Perempuan | J36: https://drive.google.com/open?id=1IuqZK1MDvBF-QJCHXfghgBFiYEvoAWbP | K36: kusm17889@gmail.com | L36: EBTAQ25-05.007 | M36: https://drive.google.com/file/d/1RG0r7j_f1DRlXA34orDGNeYRKGuwmreQ/view?usp=drivesdk
A37: 45995.388 | B37: Karbon | C37: Karbon - TPQ Qurrotul 'Ain | D37: Alif Nur Zakiyyah Akhfi | E37: Demak | F37: 42109 | G37: Nur Sahid | H37: Arni Ardiyawati | I37: Perempuan | J37: https://drive.google.com/open?id=1Ny17lnfX-4BOT0H8C84w8ILdAaOKAhfk | K37: saefudin17629@gmail.com | L37: EBTAQ25-05.008
A38: 45995.46 | B38: BMW | C38: BMW - Roudhotus Syifa | D38: GEBRIEL JUNITA AZ-ZAHRA | E38: DEMAK | F38: 42532 | G38: ROMDHON | H38: NUR HAYATI | I38: Perempuan | J38: https://drive.google.com/open?id=1N4I-rJoRqYO6-z-q8FDA3RPsKlCAo8yZ | K38: mmaruf0139@gmail.com | L38: EBTAQ25-03.004 | M38: https://drive.google.com/file/d/1YZXmYgHoUXIlrQmAIm56xGbOsPn0RHZ8/view?usp=drivesdk
A39: 45995.467 | B39: BMW | C39: BMW - Roudhotus Syifa | D39: NELY LIZA LISTIANY | E39: DEMAK | F39: 42553 | G39: NUR KHOLIS | H39: NUR AZIZAH | I39: Perempuan | J39: https://drive.google.com/open?id=1fTj32WcxxeyU5nhWY4a-9X_-EaZHo-pP | K39: mm5926704@gmail.com | L39: EBTAQ25-03.005 | M39: https://drive.google.com/file/d/1DhGseUBDz8r54aw6wcyydwSL3BTLCH8x/view?usp=drivesdk
A40: 45995.532 | B40: Karbon | C40: Karbon - TPQ Nahdlotul Qur'an | D40: RARA TRI APRILIANA | E40: DEMAK | F40: 42109 | G40: RAKIMIN | H40: ROMLAH | I40: Perempuan | J40: https://drive.google.com/open?id=1sdEp7nkHPIHNea7-o8dNU9j0J6t_RvVp | K40: nahdlotulqurantpq1@gmail.com | L40: EBTAQ25-05.009
A41: 45995.542 | B41: Karbon | C41: Karbon - TPQ Nahdlotul Qur'an | D41: naura latisha aquina | E41: demak | F41: 42349 | G41: ahmad saefudin | H41: ropiah | I41: Perempuan | J41: https://drive.google.com/open?id=1b7iLYDeTO2_GAwCfNxeuWQ4j5H8DrQ6f | K41: ainamoena406@gmail.com | L41: EBTAQ25-05.010
A42: 45995.548 | B42: Karbon | C42: Karbon - TPQ Nahdlotul Qur'an | D42: NABILA NAILU ZAKIYYATUL MUNA | E42: DEMAK | F42: 42330 | G42: MUHAMAD KOERI | H42: ROMLAH | I42: Perempuan | J42: https://drive.google.com/open?id=1J6hgh25lrq6QxILNjyQ0YHMzEyONzlLz | K42: tpqnahdzathulquran@gmail.com | L42: EBTAQ25-05.011
A43: 45995.552 | B43: Karbon | C43: Karbon - TPQ Nahdlotul Qur'an | D43: DANISHA NAIRA NAJMI | E43: DEMAK | F43: 42546 | G43: MOH AGUS SALIM | H43: NURUL KHOIRIYAH | I43: Perempuan | J43: https://drive.google.com/open?id=1f7BauV_HURJdeOaOy528B_BsEqCXVuVk | K43: shivaalizzah@gmail.com | L43: EBTAQ25-05.012
A44: 45995.556 | B44: Karbon | C44: Karbon - TPQ Nahdlotul Qur'an | D44: TALITHA MUTIA AZZAHRA | E44: DEMAK | F44: 42668 | G44: AKHID IRIADI | H44: IKA SILVIA MARTANIA | I44: Perempuan | J44: https://drive.google.com/open?id=1ScalFEZn28SCwSvF1URw2lzAg2dTrZcW | K44: drah16022@gmail.com | L44: EBTAQ25-05.013
A45: 45995.682 | B45: Karbon | C45: Karbon - TPQ Nahdlotul Qur'an | D45: KHOIRUNNISA SALSABILA | E45: SEMARANG | F45: 42393 | G45: MIFTAHUL HUDA | H45: AINUL MAFROKAH | I45: Perempuan | J45: https://drive.google.com/open?id=15osqENtLHUOcWDqiYr-GyV9HvWcOgpFL | K45: farikahica@gmail.com | L45: EBTAQ25-05.014
A46: 45996.636 | B46: Demak | C46: SDIT KOTAWALI | D46: FATIMATUZ ZAHRA ADNAN | E46: SEMARANG | F46: 41794 | G46: AHMAD ADNAN | H46: UCI NOVIATI | I46: Perempuan | J46: https://drive.google.com/open?id=19tCLQWzxYlOb3-WPS90V1hNJ0Hq1rBlO | K46: salwaazzlea@gmail.com | L46: EBTAQ25-01.130 | M46: https://drive.google.com/file/d/14Nv3YO6iRspLKQg4h1unQeYheO1cExyR/view?usp=drivesdk
A47: 45997.351 | B47: Karbon | C47: Karbon - TPQ Masithoh II | D47: Muhammad Danish Arkana | E47: Pekalongan | F47: 42133 | G47: Muhamad Rofiq | H47: Tri Umiati | I47: Laki-laki | J47: https://drive.google.com/open?id=1eZ7LPhPCfn0H3eIXC19-y6wrBpmN9vqK | K47: uswatunkhasanahh286@gmail.com | L47: EBTAQ25-05.015
A48: 45998.482 | B48: Demak | C48: Karbon - TPQ Qurrotul 'Ain | D48: Sabrina aqila rahma | E48: Demak | F48: 42114 | G48: Khoirul latif | H48: Lukluatul khadziroh | I48: Perempuan | J48: https://drive.google.com/open?id=1EursjyoKVsOOdaX7_nmRhOD_sLJ_Xqpf | K48: aqilafifi1508@gmail.com | L48: EBTAQ25-01.131 | M48: https://drive.google.com/file/d/1duWKV1kvFWgFCWKHuZDEt35jKOtxj-wr/view?usp=drivesdk
A49: 45998.488 | B49: Karbon | C49: Karbon - TPQ Qurrotul 'Ain | D49: Maulida Naila nabila | E49: Demak,12 Desember 2016 | F49: 42716 | G49: Muhammad mashuri | H49: Amin munzainah | I49: Perempuan | J49: https://drive.google.com/open?id=1lXJ91qEoINauEsJBwCjp9JHhk5opuCoa | K49: maulidanailanabila@gmail.com | L49: EBTAQ25-05.016
A50: 45998.495 | B50: Karbon | C50: Karbon - TPQ Qurrotul 'Ain | D50: Kiandra Aqila Hatmiko | E50: Semarang | F50: 41811 | G50: Anjar tri hatmiko | H50: Retno murdianingrum | I50: Perempuan | J50: https://drive.google.com/open?id=1Z73nzZVBDsXoeelvZ2Obqnt6XdhGo7pk | K50: anjarhatmiko@gmail.com | L50: EBTAQ25-05.017
A51: 45998.554 | B51: Karbon | C51: Karbon - TPQ Qurrotul 'Ain | D51: Maylani Ananda Putri | E51: Demak | F51: 42129 | G51: Fendy Agus Riyanto | H51: Iatikomah | I51: Perempuan | J51: https://drive.google.com/open?id=1KZ3BdpHkZJ91SxoNy2OxucX875ogiOMT | K51: islanisti@gmail.com | L51: EBTAQ25-05.018
A52: 45998.557 | B52: Demak | C52: Karbon - TPQ Qurrotul 'Ain | D52: ANA NAFISATUZZAHRO | E52: SEMARANG | F52: 42354 | G52: KARTONO | H52: NURUL HIKMAH | I52: Perempuan | J52: https://drive.google.com/open?id=1RmOfQW2PGka_V6WNPufdkcdoh--62LC- | K52: nnurulhikmah66@gmail.com | L52: EBTAQ25-01.132 | M52: https://drive.google.com/file/d/1PO8E7oS2ehB8cYadjZVFLTgXGjGQI0Rk/view?usp=drivesdk
A53: 45998.581 | B53: Demak | C53: Karbon - TPQ Qurrotul 'Ain | D53: Ahmad Muiz Halim | E53: Demak | F53: 42259 | G53: Sutiyono | H53: Novita Murtiyani | I53: Laki-laki | J53: https://drive.google.com/open?id=1GVSfUtAd-VG7N2w11azVOuPqlJ_pNFuw | K53: sutiyono181196@gmail.com | L53: EBTAQ25-01.133 | M53: https://drive.google.com/file/d/1DTrIoNS5cMoRVmaf0qupTwwlTE7YxG0M/view?usp=drivesdk
A54: 45998.64 | B54: Demak | C54: Karbon - TPQ Qurrotul 'Ain | D54: Ahmad Muiz halim | E54: Demak | F54: 42259 | G54: Sutiyono | H54: Novitamurtiyani | I54: Laki-laki | J54: https://drive.google.com/open?id=1oQsAvkXWCUF9n6b2_aeH4kFyF8shv37- | K54: ahmadmuishalim@gmail.com | L54: EBTAQ25-01.134 | M54: https://drive.google.com/file/d/16q53V4Laz3VSZSD_KyTHH57gFohSyxWP/view?usp=drivesdk
A55: 45998.649 | B55: Demak | C55: Karbon - TPQ Qurrotul 'Ain | D55: ahmad muiz halim | E55: DEMAK | F55: 42347 | G55: sutiyono | H55: novita murtiyani | I55: Laki-laki | J55: https://drive.google.com/open?id=14E5FgdJRCNN0IW5-JZpQBrIEikxE3YJ1 | K55: putraares16@gmail.com | L55: EBTAQ25-01.135 | M55: https://drive.google.com/file/d/1kprFT6bfGHlELBKpdd_wHDR2CaFUqKvH/view?usp=drivesdk
A56: 45998.668 | B56: Demak | C56: Karbon - TPQ Qurrotul 'Ain | D56: Ahmad muiz halim | E56: Demak | F56: 42347 | G56: Sutiyono | H56: Murtiyani | I56: Laki-laki | J56: https://drive.google.com/open?id=1lIcEYP_y7vtj35IiBeu0Avjean_3jfWO | K56: nunkciiu@gmail.com | L56: EBTAQ25-01.136 | M56: https://drive.google.com/file/d/1d2D3VZ5cR9VXYEmbLc3AhLPyv0yomnPB/view?usp=drivesdk
A57: 45998.671 | B57: Demak | C57: Karbon - TPQ Qurrotul 'Ain | D57: Muhammad Revan Putra pambudi | E57: Demak | F57: 42217 | G57: Galuh eka pambudi | H57: Sumi kastutik | I57: Laki-laki | J57: https://drive.google.com/open?id=12S2kwR_D4ywJtsZGWeVh4sFmp_StkTPu | K57: revanpamudi@gmail.com | L57: EBTAQ25-01.137 | M57: https://drive.google.com/file/d/15bukjPSIKhtn074THOHOpcBmOU0pC7KY/view?usp=drivesdk
A58: 45998.693 | B58: Demak | C58: Dewoka - Nuzulur Rohmah | D58: Syaffira Maharani Putri Fie | E58: Demak | F58: 41692 | G58: Fahruddin Lutfiei | H58: Eka Prasetya Ningrum | I58: Perempuan | J58: https://drive.google.com/open?id=1sK6HeLqWPPg_hDzXX8TStXEgzC_J0OtB | K58: defatimah8@gmail.com | L58: EBTAQ25-01.138 | M58: https://drive.google.com/file/d/14jQTZGNIoxylLqXsorOx9I5LHpoFAl3e/view?usp=drivesdk
A59: 45998.742 | B59: Karbon | C59: Karbon - TPQ Qurrotul 'Ain | D59: RAFA AHMAD ANSHORI | E59: Semarang | F59: 42628 | G59: A. KHARIS MUKTAFI | H59: ANNI FARICHAH | I59: Laki-laki | J59: https://drive.google.com/open?id=1pOsKMAA76XvfpEVBXDNLQ8i4PUMEGwjQ | K59: rafakaka369@gmail.com | L59: EBTAQ25-05.019
A60: 45998.743 | B60: Karbon | C60: Karbon - TPQ Qurrotul 'Ain | D60: Alif nur zakiyyah akhfi | E60: Demak | F60: 42108 | G60: Nur sahid | H60: Arni ardiyawati | I60: Perempuan | J60: https://drive.google.com/open?id=1JYaLZxWPQGhq2uzPz2Xkuujdbg3s7QwV | K60: sahidn688@gmail.com | L60: EBTAQ25-05.020
A61: 45998.761 | B61: Karbon | C61: Karbon - Hidayatul Mubtadi'in | D61: DIAS WAHYU PRATAMA | E61: Demak | F61: 40836 | G61: Muhamad Nasi'in | H61: Rondiyah | I61: Laki-laki | J61: https://drive.google.com/open?id=1E0fThNgGcTVzGkiYXgSDjtsMTaiijxAO | K61: dito.cahsmc04@gmail.com | L61: EBTAQ25-05.021
A62: 45998.795 | B62: Karbon | C62: Karbon - TPQ Qurrotul 'Ain | D62: Muhammad Khalid Sutarji | E62: Demak | F62: 41588 | G62: Sutarji | H62: Novrida Ningsih Simangunsong | I62: Laki-laki | J62: https://drive.google.com/open?id=1FhWJy2sxBunzCyAWQEWREA6v6ALf73JP | K62: bputriaf@gmail.com | L62: EBTAQ25-05.022
...

Sheet Lembar3
A2: No. | B2: ID Peserta | C2: Nama Lengkap | D2: L/P | E2: TEMPAT LAHIR | F2: TANGGAL LAHIR | G2: BIN | H2: BINTI | I2: Foto | J2: Asal Lembaga | K2: Kehadiran | L2: ACAK | M2: SOAL GRB
A3: 228 | B3: =Lembar2!L2 -> EBTAQ25-06.001 | C3: =Lembar2!D2 -> SITI NUR SALSABILA | D3: =Lembar2!I2 -> Perempuan | E3: =Lembar2!E2 -> Kendal | F3: =Lembar2!F2 -> 40885 | G3: =Lembar2!G2 -> SHOLIKHIN | H3: =Lembar2!H2 -> NGASTI'AH | I3: =VLOOKUP(B3,Lembar1!A$4:H$175,8,FALSE) -> BIO_Images/EBTAQ25-06.001.jpg | J3: =Lembar2!C2 -> Mranggen - Futuhiyyah
A4: 229 | B4: =Lembar2!L3 -> EBTAQ25-01.111 | C4: =Lembar2!D3 -> WAKHIDATUN NAILIS SA'ADAH | D4: =Lembar2!I3 -> Perempuan | E4: =Lembar2!E3 -> Demak | F4: =Lembar2!F3 -> 42501 | G4: =Lembar2!G3 -> MAD SOLEH | H4: =Lembar2!H3 -> SITI KHOLIFAH | I4: =VLOOKUP(B4,Lembar1!A$4:H$175,8,FALSE) -> BIO_Images/EBTAQ25-01.111.jpg | J4: =Lembar2!C3 -> Demak - TPQ KH ALJAZERI
A5: 230 | B5: =Lembar2!L4 -> EBTAQ25-01.112 | C5: =Lembar2!D4 -> Atika Zahra Latifa | D5: =Lembar2!I4 -> Perempuan | E5: =Lembar2!E4 -> Demak | F5: =Lembar2!F4 -> 41776 | G5: =Lembar2!G4 -> Abdul Hadi | H5: =Lembar2!H4 -> Tika Ikhwal Maryana | I5: =VLOOKUP(B5,Lembar1!A$4:H$175,8,FALSE) -> BIO_Images/EBTAQ25-01.112atika - safaroh nizam | J5: =Lembar2!C4 -> Demak - TPQ KH ALJAZERI
A6: 231 | B6: =Lembar2!L5 -> EBTAQ25-01.113 | C6: =Lembar2!D5 -> Keisha Laila Fajrina | D6: =Lembar2!I5 -> Perempuan | E6: =Lembar2!E5 -> Demak | F6: =Lembar2!F5 -> 42488 | G6: =Lembar2!G5 -> Mohamad Fatkhan | H6: =Lembar2!H5 -> Sukinah | I6: =VLOOKUP(B6,Lembar1!A$4:H$175,8,FALSE) -> BIO_Images/EBTAQ25-01.113.jpg | J6: =Lembar2!C5 -> Demak - TPQ ALHADID
A7: 232 | B7: =Lembar2!L6 -> EBTAQ25-01.114 | C7: =Lembar2!D6 -> ADELIA KHAIRA WILDA | D7: =Lembar2!I6 -> Perempuan | E7: =Lembar2!E6 -> DEMAK | F7: =Lembar2!F6 -> 42037 | G7: =Lembar2!G6 -> ZAENAL ABIDIN | H7: =Lembar2!H6 -> JIJIN TURIASIH | I7: =VLOOKUP(B7,Lembar1!A$4:H$175,8,FALSE) -> BIO_Images/EBTAQ25-01.114.jpg | J7: =Lembar2!C6 -> Demak - TPQ ALHADID
A8: 233 | B8: =Lembar2!L7 -> EBTAQ25-01.115 | C8: =Lembar2!D7 -> Annisa faiha | D8: =Lembar2!I7 -> Perempuan | E8: =Lembar2!E7 -> Demak | F8: =Lembar2!F7 -> 42841 | G8: =Lembar2!G7 -> Kholil Bisri | H8: =Lembar2!H7 -> Himmatul Ulliya | I8: =VLOOKUP(B8,Lembar1!A$4:H$175,8,FALSE) -> BIO_Images/EBTAQ25-01.115.jpg | J8: =Lembar2!C7 -> Demak - TPQ ALHADID
A9: 234 | B9: =Lembar2!L8 -> EBTAQ25-01.116 | C9: =Lembar2!D8 -> octafia ayu rahmawati | D9: =Lembar2!I8 -> Perempuan | E9: =Lembar2!E8 -> Demak | F9: =Lembar2!F8 -> 42307 | G9: =Lembar2!G8 -> purwadi | H9: =Lembar2!H8 -> saudah | I9: =VLOOKUP(B9,Lembar1!A$4:H$175,8,FALSE) -> BIO_Images/EBTAQ25-01.116.jpg | J9: =Lembar2!C8 -> Demak - TPQ ALHADID
A10: 235 | B10: =Lembar2!L9 -> EBTAQ25-01.117 | C10: =Lembar2!D9 -> AQILA QURROTU A'YUN | D10: =Lembar2!I9 -> Perempuan | E10: =Lembar2!E9 -> Demak | F10: =Lembar2!F9 -> 42577 | G10: =Lembar2!G9 -> Sucipto | H10: =Lembar2!H9 -> Kholisoh | I10: =VLOOKUP(B10,Lembar1!A$4:H$175,8,FALSE) -> BIO_Images/EBTAQ25-01.117.jpg | J10: =Lembar2!C9 -> Demak - TPQ ALHADID
A11: 236 | B11: =Lembar2!L10 -> EBTAQ25-01.118 | C11: =Lembar2!D10 -> Nurul Fauziyah Ramadhani | D11: =Lembar2!I10 -> Perempuan | E11: =Lembar2!E10 -> Demak | F11: =Lembar2!F10 -> 41482 | G11: =Lembar2!G10 -> Muhidin | H11: =Lembar2!H10 -> Sri kumaidah | I11: =VLOOKUP(B11,Lembar1!A$4:H$175,8,FALSE) -> BIO_Images/EBTAQ25-01.118.jpg | J11: =Lembar2!C10 -> Demak - TPQ ALHADID
A12: 237 | B12: =Lembar2!L11 -> EBTAQ25-01.119 | C12: =Lembar2!D11 -> Aisya Faiha Maulidya | D12: =Lembar2!I11 -> Perempuan | E12: =Lembar2!E11 -> Demak | F12: =Lembar2!F11 -> 42729 | G12: =Lembar2!G11 -> Masri | H12: =Lembar2!H11 -> Kasiroh | I12: =VLOOKUP(B12,Lembar1!A$4:H$175,8,FALSE) -> BIO_Images/EBTAQ25-01.119.jpg | J12: =Lembar2!C11 -> Demak - TPQ ALHADID
A13: 238 | B13: =Lembar2!L12 -> EBTAQ25-06.002 | C13: =Lembar2!D12 -> AQILA RAISA AILANI MA'ARIF | D13: =Lembar2!I12 -> Perempuan | E13: =Lembar2!E12 -> Semarang | F13: =Lembar2!F12 -> 41853 | G13: =Lembar2!G12 -> Khusnul Ma'arif | H13: =Lembar2!H12 -> Nur Khoiroh Wijayanti | I13: =VLOOKUP(B13,Lembar1!A$4:H$175,8,FALSE) -> BIO_Images/EBTAQ25-06.002.jpg | J13: =Lembar2!C12 -> Mranggen - Darul qur'an
A14: 239 | B14: =Lembar2!L13 -> EBTAQ25-06.003 | C14: =Lembar2!D13 -> Ahmad Fakhryl Mubarok | D14: =Lembar2!I13 -> Laki-laki | E14: =Lembar2!E13 -> Demak | F14: =Lembar2!F13 -> 41787 | G14: =Lembar2!G13 -> Anton Husni Mubarok | H14: =Lembar2!H13 -> Akmalia | I14: =VLOOKUP(B14,Lembar1!A$4:H$175,8,FALSE) -> BIO_Images/EBTAQ25-06.003.jpg | J14: =Lembar2!C13 -> Mranggen - Darul qur'an
... A469: 694 | B469: =Lembar2!L468 -> EBTAQ25-01.330 | C469: =Lembar2!D468 -> AZWA LAYYINATUS SALIMAH | D469: =Lembar2!I468 -> Perempuan | E469: =Lembar2!E468 -> DEMAK | F469: =Lembar2!F468 -> 42588 | G469: =Lembar2!G468 -> AGUS SALIM | H469: =Lembar2!H468 -> NUR FAIZAH | I469: =VLOOKUP(B469,Lembar1!A$4:H$175,8,FALSE) -> #N/A | J469: =Lembar2!C468 -> Demak - TPQ ALHUSNA (MI)

Sheet Lembar2
A1: Timestamp | B1: Pilih Korcam | C1: Asal Lembaga / TPQ | D1: Nama Lengkap (Sesuai Akta) | E1: Tempat Lahir | F1: Tanggal Lahir | G1: Nama Ayah | H1: Nama Ibu | I1: Jenis Kelamin | J1: Kirim Pas Foto Ukuran PostCard | K1: Email Address | L1: ID Pendaftaran | M1: Link PDF
A2: 45967.632 | B2: Mranggen | C2: Mranggen - Futuhiyyah | D2: SITI NUR SALSABILA | E2: Kendal | F2: 40885 | G2: SHOLIKHIN | H2: NGASTI'AH | I2: Perempuan | J2: https://drive.google.com/open?id=1mrEM8U6G0fnxB_WTM_uGprNxAl7eOq0e | K2: fatimatuzzahra828@gmail.com | L2: EBTAQ25-06.001
A3: 45968.45 | B3: Demak | C3: Demak - TPQ KH ALJAZERI | D3: WAKHIDATUN NAILIS SA'ADAH | E3: Demak | F3: 42501 | G3: MAD SOLEH | H3: SITI KHOLIFAH | I3: Perempuan | J3: https://drive.google.com/open?id=1CxbLWtvE5o0cP9rqTU94xgy6vevWYehK | K3: nikmaturrosyidah4@gmail.com | L3: EBTAQ25-01.111 | M3: https://drive.google.com/file/d/149ZcJWZKRBGgnZcEt-5zAFELzAWTeuhf/view?usp=drivesdk
A4: 45968.495 | B4: Demak | C4: Demak - TPQ KH ALJAZERI | D4: Atika Zahra Latifa | E4: Demak | F4: 41776 | G4: Abdul Hadi | H4: Tika Ikhwal Maryana | I4: Perempuan | J4: https://drive.google.com/open?id=1-nHm9EXUgpOrxGSEEER_gd2MzcM0-AUU | K4: safarohnizam@gmail.com | L4: EBTAQ25-01.112 | M4: https://drive.google.com/file/d/17FDEWneIX3pFjiXjVZWejPQ5zwFH3zq7/view?usp=drivesdk
A5: 45969.375 | B5: Demak | C5: Demak - TPQ ALHADID | D5: Keisha Laila Fajrina | E5: Demak | F5: 42488 | G5: Mohamad Fatkhan | H5: Sukinah | I5: Perempuan | J5: https://drive.google.com/open?id=1f5SwUGtvDG6QgH4U3gKJlQTxwe1MwDIH | K5: hikmatulishaq@gmail.com | L5: EBTAQ25-01.113 | M5: https://drive.google.com/file/d/1S1EnzUcSIlncCOXIW-y-UYZySpxnWtrK/view?usp=drivesdk
A6: 45969.701 | B6: Demak | C6: Demak - TPQ ALHADID | D6: ADELIA KHAIRA WILDA | E6: DEMAK | F6: 42037 | G6: ZAENAL ABIDIN | H6: JIJIN TURIASIH | I6: Perempuan | J6: https://drive.google.com/open?id=1x0WjMDp1vEONPYIFlWgEEhmV92TyO6i0 | K6: nakhilajihan@gmail.com | L6: EBTAQ25-01.114 | M6: https://drive.google.com/file/d/1EvjlRBAVrIAOWUp1uoIG7LEz7ATejl9R/view?usp=drivesdk
A7: 45969.707 | B7: Demak | C7: Demak - TPQ ALHADID | D7: Annisa faiha | E7: Demak | F7: 42841 | G7: Kholil Bisri | H7: Himmatul Ulliya | I7: Perempuan | J7: https://drive.google.com/open?id=17le2Igs59p_HTSCsAR3GNNJt2RIMSDCY | K7: faihaannisa632@gmail.com | L7: EBTAQ25-01.115 | M7: https://drive.google.com/file/d/1XjXJtEPl3B4Z5iGDIg75rMCNXz0i-1_f/view?usp=drivesdk
A8: 45969.71 | B8: Demak | C8: Demak - TPQ ALHADID | D8: octafia ayu rahmawati | E8: Demak | F8: 42307 | G8: purwadi | H8: saudah | I8: Perempuan | J8: https://drive.google.com/open?id=11JLbasjtEy0YNiuuHAGDR05kzL8r2mTs | K8: khusna8765@gmail.com | L8: EBTAQ25-01.116 | M8: https://drive.google.com/file/d/1sYSdtjmuBXfAU8eS9sDn2m_a-iJScwgf/view?usp=drivesdk
A9: 45969.713 | B9: Demak | C9: Demak - TPQ ALHADID | D9: AQILA QURROTU A'YUN | E9: Demak | F9: 42577 | G9: Sucipto | H9: Kholisoh | I9: Perempuan | J9: https://drive.google.com/open?id=1rW0U4BxDjbyOl2mhyPLhvdRdedM758eF | K9: suciptokarangmlati@gmail.com | L9: EBTAQ25-01.117 | M9: https://drive.google.com/file/d/1lud1iW1ZfaSG2vQU33r5nidI79TTuo11/view?usp=drivesdk
A10: 45969.714 | B10: Demak | C10: Demak - TPQ ALHADID | D10: Nurul Fauziyah Ramadhani | E10: Demak | F10: 41482 | G10: Muhidin | H10: Sri kumaidah | I10: Perempuan | J10: https://drive.google.com/open?id=1JNVvb5MHz_uR3Se5WpFia029sUNc5CvC | K10: fikriyahhd@gmail.com | L10: EBTAQ25-01.118 | M10: https://drive.google.com/file/d/1kd4F2IwGWQ2a0pKywjKyKjQDpOyfseEK/view?usp=drivesdk
A11: 45969.722 | B11: Demak | C11: Demak - TPQ ALHADID | D11: Aisya Faiha Maulidya | E11: Demak | F11: 42729 | G11: Masri | H11: Kasiroh | I11: Perempuan | J11: https://drive.google.com/open?id=1TWXX2Dc3Rz4kjWJ-tCJAgX26qkrP6gvh | K11: mawarmelati1503@gmail.com | L11: EBTAQ25-01.119 | M11: https://drive.google.com/file/d/15fXGhFlhRT0fllOpTzons26Mhuoo_NQz/view?usp=drivesdk
A12: 45972.006 | B12: Mranggen | C12: Mranggen - Darul qur'an | D12: AQILA RAISA AILANI MA'ARIF | E12: Semarang | F12: 41853 | G12: Khusnul Ma'arif | H12: Nur Khoiroh Wijayanti | I12: Perempuan | J12: https://drive.google.com/open?id=1kV7426-pZepQwruh-h4gakwsSJ1VIWc1 | K12: rmaghfiroh881@gmail.com | L12: EBTAQ25-06.002 | M12: https://drive.google.com/file/d/1gt_POAXQ21jIiShA8tSKzkmzmGd0Kr9g/view?usp=drivesdk
A13: 45972.036 | B13: Mranggen | C13: Mranggen - Darul qur'an | D13: Ahmad Fakhryl Mubarok | E13: Demak | F13: 41787 | G13: Anton Husni Mubarok | H13: Akmalia | I13: Laki-laki | J13: https://drive.google.com/open?id=1w25YpuRXIefDgcDRiGW1VWfusl3lFqcR | K13: zakiyazaa231@gmail.com | L13: EBTAQ25-06.003 | M13: https://drive.google.com/file/d/1Z8VAly-FHrt4-JIjrjnOWfb91tQRMS3H/view?usp=drivesdk
A14: 45972.041 | B14: Mranggen | C14: Mranggen - Darul qur'an | D14: Ayyash | E14: Semarang | F14: 42271 | G14: Dian Hadi Saputra | H14: May Kurniawati | I14: Laki-laki | J14: https://drive.google.com/open?id=1jOANmbzmyYjUM6tdjRiWi4fMqMz5vD3g | K14: dinakhulala12@gmail.com | L14: EBTAQ25-06.004 | M14: https://drive.google.com/file/d/18qA0XYpW8znmpl-jwf8kLxpd3vcgDhl7/view?usp=drivesdk
... A37: 45994.96 | B37: Karbon | C37: Karbon - TPQ MASITHOH 8 | D37: Shakila Dzahin Nicky Azzahra | E37: Demak | F37: 42604 | G37: Nicky Yulianto | H37: Mimin Afita Sari | I37: Perempuan | J37: https://drive.google.com/open?id=1IuqZK1MDvBF-QJCHXfghgBFiYEvoAWbP | K37: kusm17889@gmail.com | L37: EBTAQ25-05.007 | M37: https://drive.google.com/file/d/1RG0r7j_f1DRlXA34orDGNeYRKGuwmreQ/view?usp=drivesdk
A38: 45995.388 | B38: Karbon | C38: Karbon - TPQ Qurrotul 'Ain | D38: Alif Nur Zakiyyah Akhfi | E38: Demak | F38: 42109 | G38: Nur Sahid | H38: Arni Ardiyawati | I38: Perempuan | J38: https://drive.google.com/open?id=1Ny17lnfX-4BOT0H8C84w8ILdAaOKAhfk | K38: saefudin17629@gmail.com | L38: EBTAQ25-05.008
A39: 45995.46 | B39: BMW | C39: BMW - Roudhotus Syifa | D39: GEBRIEL JUNITA AZ-ZAHRA | E39: DEMAK | F39: 42532 | G39: ROMDHON | H39: NUR HAYATI | I39: Perempuan | J39: https://drive.google.com/open?id=1N4I-rJoRqYO6-z-q8FDA3RPsKlCAo8yZ | K39: mmaruf0139@gmail.com | L39: EBTAQ25-03.004 | M39: https://drive.google.com/file/d/1YZXmYgHoUXIlrQmAIm56xGbOsPn0RHZ8/view?usp=drivesdk
A40: 45995.467 | B40: BMW | C40: BMW - Roudhotus Syifa | D40: NELY LIZA LISTIANY | E40: DEMAK | F40: 42553 | G40: NUR KHOLIS | H40: NUR AZIZAH | I40: Perempuan | J40: https://drive.google.com/open?id=1fTj32WcxxeyU5nhWY4a-9X_-EaZHo-pP | K40: mm5926704@gmail.com | L40: EBTAQ25-03.005 | M40: https://drive.google.com/file/d/1DhGseUBDz8r54aw6wcyydwSL3BTLCH8x/view?usp=drivesdk
A41: 45995.532 | B41: Karbon | C41: Karbon - TPQ Nahdlotul Qur'an | D41: RARA TRI APRILIANA | E41: DEMAK | F41: 42109 | G41: RAKIMIN | H41: ROMLAH | I41: Perempuan | J41: https://drive.google.com/open?id=1sdEp7nkHPIHNea7-o8dNU9j0J6t_RvVp | K41: nahdlotulqurantpq1@gmail.com | L41: EBTAQ25-05.009
A42: 45995.542 | B42: Karbon | C42: Karbon - TPQ Nahdlotul Qur'an | D42: naura latisha aquina | E42: demak | F42: 42349 | G42: ahmad saefudin | H42: ropiah | I42: Perempuan | J42: https://drive.google.com/open?id=1b7iLYDeTO2_GAwCfNxeuWQ4j5H8DrQ6f | K42: ainamoena406@gmail.com | L42: EBTAQ25-05.010
A43: 45995.548 | B43: Karbon | C43: Karbon - TPQ Nahdlotul Qur'an | D43: NABILA NAILU ZAKIYYATUL MUNA | E43: DEMAK | F43: 42330 | G43: MUHAMAD KOERI | H43: ROMLAH | I43: Perempuan | J43: https://drive.google.com/open?id=1J6hgh25lrq6QxILNjyQ0YHMzEyONzlLz | K43: tpqnahdzathulquran@gmail.com | L43: EBTAQ25-05.011
A44: 45995.552 | B44: Karbon | C44: Karbon - TPQ Nahdlotul Qur'an | D44: DANISHA NAIRA NAJMI | E44: DEMAK | F44: 42546 | G44: MOH AGUS SALIM | H44: NURUL KHOIRIYAH | I44: Perempuan | J44: https://drive.google.com/open?id=1f7BauV_HURJdeOaOy528B_BsEqCXVuVk | K44: shivaalizzah@gmail.com | L44: EBTAQ25-05.012
A45: 45995.556 | B45: Karbon | C45: Karbon - TPQ Nahdlotul Qur'an | D45: TALITHA MUTIA AZZAHRA | E45: DEMAK | F45: 42668 | G45: AKHID IRIADI | H45: IKA SILVIA MARTANIA | I45: Perempuan | J45: https://drive.google.com/open?id=1ScalFEZn28SCwSvF1URw2lzAg2dTrZcW | K45: drah16022@gmail.com | L45: EBTAQ25-05.013
A46: 45995.682 | B46: Karbon | C46: Karbon - TPQ Nahdlotul Qur'an | D46: KHOIRUNNISA SALSABILA | E46: SEMARANG | F46: 42393 | G46: MIFTAHUL HUDA | H46: AINUL MAFROKAH | I46: Perempuan | J46: https://drive.google.com/open?id=15osqENtLHUOcWDqiYr-GyV9HvWcOgpFL | K46: farikahica@gmail.com | L46: EBTAQ25-05.014
A47: 45996.636 | B47: Demak | C47: SDIT KOTAWALI | D47: FATIMATUZ ZAHRA ADNAN | E47: SEMARANG | F47: 41794 | G47: AHMAD ADNAN | H47: UCI NOVIATI | I47: Perempuan | J47: https://drive.google.com/open?id=19tCLQWzxYlOb3-WPS90V1hNJ0Hq1rBlO | K47: salwaazzlea@gmail.com | L47: EBTAQ25-01.130 | M47: https://drive.google.com/file/d/14Nv3YO6iRspLKQg4h1unQeYheO1cExyR/view?usp=drivesdk
A48: 45997.351 | B48: Karbon | C48: Karbon - TPQ Masithoh II | D48: Muhammad Danish Arkana | E48: Pekalongan | F48: 42133 | G48: Muhamad Rofiq | H48: Tri Umiati | I48: Laki-laki | J48: https://drive.google.com/open?id=1eZ7LPhPCfn0H3eIXC19-y6wrBpmN9vqK | K48: uswatunkhasanahh286@gmail.com | L48: EBTAQ25-05.015
A49: 45998.482 | B49: Demak | C49: Karbon - TPQ Qurrotul 'Ain | D49: Sabrina aqila rahma | E49: Demak | F49: 42114 | G49: Khoirul latif | H49: Lukluatul khadziroh | I49: Perempuan | J49: https://drive.google.com/open?id=1EursjyoKVsOOdaX7_nmRhOD_sLJ_Xqpf | K49: aqilafifi1508@gmail.com | L49: EBTAQ25-01.131 | M49: https://drive.google.com/file/d/1duWKV1kvFWgFCWKHuZDEt35jKOtxj-wr/view?usp=drivesdk
A50: 45998.488 | B50: Karbon | C50: Karbon - TPQ Qurrotul 'Ain | D50: Maulida Naila nabila | E50: Demak,12 Desember 2016 | F50: 42716 | G50: Muhammad mashuri | H50: Amin munzainah | I50: Perempuan | J50: https://drive.google.com/open?id=1lXJ91qEoINauEsJBwCjp9JHhk5opuCoa | K50: maulidanailanabila@gmail.com | L50: EBTAQ25-05.016
A51: 45998.495 | B51: Karbon | C51: Karbon - TPQ Qurrotul 'Ain | D51: Kiandra Aqila Hatmiko | E51: Semarang | F51: 41811 | G51: Anjar tri hatmiko | H51: Retno murdianingrum | I51: Perempuan | J51: https://drive.google.com/open?id=1Z73nzZVBDsXoeelvZ2Obqnt6XdhGo7pk | K51: anjarhatmiko@gmail.com | L51: EBTAQ25-05.017
A52: 45998.554 | B52: Karbon | C52: Karbon - TPQ Qurrotul 'Ain | D52: Maylani Ananda Putri | E52: Demak | F52: 42129 | G52: Fendy Agus Riyanto | H52: Iatikomah | I52: Perempuan | J52: https://drive.google.com/open?id=1KZ3BdpHkZJ91SxoNy2OxucX875ogiOMT | K52: islanisti@gmail.com | L52: EBTAQ25-05.018
A53: 45998.557 | B53: Demak | C53: Karbon - TPQ Qurrotul 'Ain | D53: ANA NAFISATUZZAHRO | E53: SEMARANG | F53: 42354 | G53: KARTONO | H53: NURUL HIKMAH | I53: Perempuan | J53: https://drive.google.com/open?id=1RmOfQW2PGka_V6WNPufdkcdoh--62LC- | K53: nnurulhikmah66@gmail.com | L53: EBTAQ25-01.132 | M53: https://drive.google.com/file/d/1PO8E7oS2ehB8cYadjZVFLTgXGjGQI0Rk/view?usp=drivesdk
A54: 45998.581 | B54: Demak | C54: Karbon - TPQ Qurrotul 'Ain | D54: Ahmad Muiz Halim | E54: Demak | F54: 42259 | G54: Sutiyono | H54: Novita Murtiyani | I54: Laki-laki | J54: https://drive.google.com/open?id=1GVSfUtAd-VG7N2w11azVOuPqlJ_pNFuw | K54: sutiyono181196@gmail.com | L54: EBTAQ25-01.133 | M54: https://drive.google.com/file/d/1DTrIoNS5cMoRVmaf0qupTwwlTE7YxG0M/view?usp=drivesdk
A55: 45998.64 | B55: Demak | C55: Karbon - TPQ Qurrotul 'Ain | D55: Ahmad Muiz halim | E55: Demak | F55: 42259 | G55: Sutiyono | H55: Novitamurtiyani | I55: Laki-laki | J55: https://drive.google.com/open?id=1oQsAvkXWCUF9n6b2_aeH4kFyF8shv37- | K55: ahmadmuishalim@gmail.com | L55: EBTAQ25-01.134 | M55: https://drive.google.com/file/d/16q53V4Laz3VSZSD_KyTHH57gFohSyxWP/view?usp=drivesdk
A56: 45998.649 | B56: Demak | C56: Karbon - TPQ Qurrotul 'Ain | D56: ahmad muiz halim | E56: DEMAK | F56: 42347 | G56: sutiyono | H56: novita murtiyani | I56: Laki-laki | J56: https://drive.google.com/open?id=14E5FgdJRCNN0IW5-JZpQBrIEikxE3YJ1 | K56: putraares16@gmail.com | L56: EBTAQ25-01.135 | M56: https://drive.google.com/file/d/1kprFT6bfGHlELBKpdd_wHDR2CaFUqKvH/view?usp=drivesdk
A57: 45998.668 | B57: Demak | C57: Karbon - TPQ Qurrotul 'Ain | D57: Ahmad muiz halim | E57: Demak | F57: 42347 | G57: Sutiyono | H57: Murtiyani | I57: Laki-laki | J57: https://drive.google.com/open?id=1lIcEYP_y7vtj35IiBeu0Avjean_3jfWO | K57: nunkciiu@gmail.com | L57: EBTAQ25-01.136 | M57: https://drive.google.com/file/d/1d2D3VZ5cR9VXYEmbLc3AhLPyv0yomnPB/view?usp=drivesdk
A58: 45998.671 | B58: Demak | C58: Karbon - TPQ Qurrotul 'Ain | D58: Muhammad Revan Putra pambudi | E58: Demak | F58: 42217 | G58: Galuh eka pambudi | H58: Sumi kastutik | I58: Laki-laki | J58: https://drive.google.com/open?id=12S2kwR_D4ywJtsZGWeVh4sFmp_StkTPu | K58: revanpamudi@gmail.com | L58: EBTAQ25-01.137 | M58: https://drive.google.com/file/d/15bukjPSIKhtn074THOHOpcBmOU0pC7KY/view?usp=drivesdk
A59: 45998.693 | B59: Demak | C59: Dewoka - Nuzulur Rohmah | D59: Syaffira Maharani Putri Fie | E59: Demak | F59: 41692 | G59: Fahruddin Lutfiei | H59: Eka Prasetya Ningrum | I59: Perempuan | J59: https://drive.google.com/open?id=1sK6HeLqWPPg_hDzXX8TStXEgzC_J0OtB | K59: defatimah8@gmail.com | L59: EBTAQ25-01.138 | M59: https://drive.google.com/file/d/14jQTZGNIoxylLqXsorOx9I5LHpoFAl3e/view?usp=drivesdk
A60: 45998.742 | B60: Karbon | C60: Karbon - TPQ Qurrotul 'Ain | D60: RAFA AHMAD ANSHORI | E60: Semarang | F60: 42628 | G60: A. KHARIS MUKTAFI | H60: ANNI FARICHAH | I60: Laki-laki | J60: https://drive.google.com/open?id=1pOsKMAA76XvfpEVBXDNLQ8i4PUMEGwjQ | K60: rafakaka369@gmail.com | L60: EBTAQ25-05.019
A61: 45998.743 | B61: Karbon | C61: Karbon - TPQ Qurrotul 'Ain | D61: Alif nur zakiyyah akhfi | E61: Demak | F61: 42108 | G61: Nur sahid | H61: Arni ardiyawati | I61: Perempuan | J61: https://drive.google.com/open?id=1JYaLZxWPQGhq2uzPz2Xkuujdbg3s7QwV | K61: sahidn688@gmail.com | L61: EBTAQ25-05.020
A62: 45998.761 | B62: Karbon | C62: Karbon - Hidayatul Mubtadi'in | D62: DIAS WAHYU PRATAMA | E62: Demak | F62: 40836 | G62: Muhamad Nasi'in | H62: Rondiyah | I62: Laki-laki | J62: https://drive.google.com/open?id=1E0fThNgGcTVzGkiYXgSDjtsMTaiijxAO | K62: dito.cahsmc04@gmail.com | L62: EBTAQ25-05.021
...

Sheet Lembar5
A1: 1 | B1: BMW - AL FALAH
A2: 2 | B2: BMW - AL KHOIRIYAH
A3: 3 | B3: BMW - AS-SA'IDIYYAH
A4: 4 | B4: BMW - AZZUMUT
A5: 5 | B5: BMW - DA'WATUL HAQ
A6: 6 | B6: BMW - HIDAYATUL MUBTADIIN
A7: 7 | B7: BMW - MATHOLIUL FALAH
A8: 8 | B8: BMW - ROUDHOTUS SYIFA
A9: 9 | B9: BMW - ROUDHOTUT THOLIBIN
A10: 10 | B10: BMW - SUBULUSSALAM
A11: 11 | B11: BMW - YANBU'UL QUR'AN
A12: 12 | B12: Demak - KBIT RA FADHOILUSYUKRIYYAH
... A58: 58 | B58: DEMAK - SDIT AZZAHRA
B59: BMW - Al Khoiriyah
B60: BMW - Al Khoiriyah
B61: BMW - As-Sa'idiyyah
B62: BMW - As-Sa'idiyyah
B63: BMW - As-Sa'idiyyah
B64: BMW - As-Sa'idiyyah
B65: BMW - As-Sa'idiyyah
B66: BMW - As-Sa'idiyyah
B67: BMW - As-Sa'idiyyah
B68: BMW - As-Sa'idiyyah
B69: BMW - As-Sa'idiyyah
B70: BMW - As-Sa'idiyyah
... B526: Demak - TPQ ITSBATU TAQWA

Sheet Lembar6
A1: NO | B1: LEMBAGA
A2: 1 | B2: BMW - AL FALAH
A3: 2 | B3: BMW - AL KHOIRIYAH
A4: 3 | B4: BMW - AS-SA'IDIYYAH
A5: 4 | B5: BMW - Azzumut Fatayat NU
A6: 5 | B6: BMW - DA'WATUL HAQ
A7: 6 | B7: BMW - HIDAYATUL MUBTADIIN
A8: 7 | B8: BMW - MATHOLIUL FALAH
A9: 8 | B9: BMW - ROUDHOTUS SYIFA
A10: 9 | B10: BMW - ROUDHOTUT THOLIBIN
A11: 10 | B11: BMW - SUBULUSSALAM
A12: 11 | B12: BMW - YANBU'UL QUR'AN
A13: 12 | B13: Demak - KBIT RA FADHOILUSYUKRIYYAH
... A81: 80 | B81: Karbon- Darussalam
B82: Tpq Raudlatul muta'allimin

Sheet Lembar7
A1: 99 | B1: EBTAQ25-01.064 | C1: CHINTYA BUNGA SYAFI'I | D1: Perempuan | E1: Demak | F1: 41770 | G1: IMAM SYAFI'I | H1: SUSI NUR FARIDA | I1: BIO_Images/EBTAQ25-01.064 - Salin.jpg | J1: Demak - TPQ ALURWATULWUSTQO | K1: Hadir
A2: 100 | B2: EBTAQ25-01.065 | C2: FAEYZA AQILAH DEWI | D2: Perempuan | E2: DEMAK | F2: 42025 | G2: WIYONO | H2: DESIANA PUSPITA SARI | I2: BIO_Images/EBTAQ25-01.065 - Salin.jpg | J2: Demak - TPQ ALURWATULWUSTQO | K2: Hadir
A3: 101 | B3: EBTAQ25-01.066 | C3: DELISHA AQEELA HERDHETA | D3: Perempuan | E3: KARANGANYAR | F3: 41780 | G3: HERI PANOTO | H3: DYAH FITASARI | I3: BIO_Images/EBTAQ25-01.066 - Salin.jpg | J3: Demak - TPQ ALURWATULWUSTQO | K3: Hadir
A4: 102 | B4: EBTAQ25-01.067 | C4: FATHIN ZUHRUFA HANTOYO PUTRI | D4: Perempuan | E4: SEMARANG | F4: 40682 | G4: SISWANDONO HANTOYO PUTRO | H4: MUSYAROFAH | I4: BIO_Images/EBTAQ25-01.067 - Salin.jpg | J4: Demak - TPQ ALURWATULWUSTQO | K4: Hadir
A5: 103 | B5: EBTAQ25-01.068 | C5: NAJWA KHAIRA WILDA | D5: Perempuan | E5: DEMAK | F5: 41734 | G5: SRIYONO | H5: NOOR SHOFIA LASTE | I5: BIO_Images/EBTAQ25-01.068 - Salin.jpg | J5: Demak - TPQ ALURWATULWUSTQO | K5: Hadir
A6: 104 | B6: EBTAQ25-01.069 | C6: ANINDITA RAFA AZZAHRA | D6: Perempuan | E6: DEMAK | F6: 41209 | G6: SUGENG PRIYADI | H6: DIAN PUJI ASTUTI | I6: BIO_Images/EBTAQ25-01.069 - Salin.jpg | J6: Demak - TPQ ALURWATULWUSTQO | K6: Hadir
A7: 1 | B7: EBTAQ25-01.014 | C7: ABDURRAHMAN | D7: Laki-laki | E7: Demak | F7: 42925 | G7: Trio Setiawan | H7: Mustaghfiroh | I7: BIO_Images/EBTAQ25-01.014 - Salin.jpg | J7: Demak - TPQ BUQ | K7: Hadir
A8: 8 | B8: EBTAQ25-01.015 | C8: ADE VINZA AL GHOZALI | D8: Laki-laki | E8: Demak | F8: 41734 | G8: Yudi Danarto | H8: Miftakhul Jannah | I8: BIO_Images/EBTAQ25-01.015.Foto.031211 - Salin.jpg | J8: Demak - TPQ BUQ | K8: Hadir
A9: 3 | B9: EBTAQ25-01.020 | C9: MAUREENATA SYAKIRA RASTRA | D9: Perempuan | E9: DEMAK | F9: 41776 | G9: SOLIKIN | H9: VIBRIA LISTHA ISLAMICA | I9: BIO_Images/EBTAQ25-01.020.Foto.031345 - Salin.jpg | J9: Demak - TPQ BUQ | K9: Hadir
A10: 4 | B10: EBTAQ25-01.021 | C10: FIKO PUTRA MAHENDRA | D10: Laki-laki | E10: DEMAK | F10: 42033 | G10: EKO PRIYANTO | H10: FITRI YUNITA SARI | I10: BIO_Images/EBTAQ25-01.021.Foto.031447 - Salin.jpg | J10: Demak - TPQ BUQ | K10: Hadir
A11: 5 | B11: EBTAQ25-01.022 | C11: RETNO ASTUTI DEWI | D11: Perempuan | E11: DEMAK | F11: 42456 | G11: TIGOR RAHMAN HAKIM | H11: WAHYU PUJI ASTUTI | I11: BIO_Images/EBTAQ25-01.022 - Salin.jpg | J11: Demak - TPQ BUQ | K11: Hadir
A12: 6 | B12: EBTAQ25-01.023 | C12: AUFAR FATIH EL MISHBAHI | D12: Laki-laki | E12: DEMAK | F12: 42020 | G12: ALI ARIFIN | H12: UMI KUSRIYATI | I12: BIO_Images/EBTAQ25-01.023 - Salin.jpg | J12: Demak - TPQ BUQ | K12: Hadir
... A227: 227 | B227: EBTAQ25-03.105 | C227: GIGIH PRADANA PUTRA WULANTORO | D227: Laki-laki | E227: Demak | F227: 41009 | G227: NURI CAHYO WULANTORO | H227: SITI ZULIATI | I227: BIO_Images/EBTAQ25-03.105.Foto.154908.jpg | J227: DEWOKA - LATANSA | K227: Hadir
A228: 228 | B228: EBTAQ25.03.009 | C228: ALFIAH JULIANTI | D228: Perempuan | E228: DEMAK | F228: 41826 | G228: ACHSANU ROHIM | H228: DEWI KHUSAEMAH | I228: BIO_Images/EBTAQ25-03.009.jpg | J228: BMW - Al Khoiriyah
A229: 229 | B229: EBTAQ25.03.010 | C229: NUFIKHO SOFARA KHOIRIYAH | D229: Perempuan | E229: DEMAK | F229: 41995 | G229: ACHMAD SIFULFAZI | H229: LAIKHATUN | I229: BIO_Images/EBTAQ25-03.010.jpg | J229: BMW - Al Khoiriyah
A230: 230 | B230: EBTAQ25.03.043 | C230: AZRIL RASYA ABQORY | D230: Laki-laki | E230: DEMAK | F230: 42478 | G230: AHMAD SUPRAPTO | H230: DURROTUN NI'MAH | I230: BIO_Images/EBTAQ25-03.043.jpg | J230: BMW - As-Sa'idiyyah
A231: 231 | B231: EBTAQ25.03.071 | C231: MUHAMMAD FAHMI AMMAR | D231: Laki-laki | E231: DEMAK | F231: 41758 | G231: ABU HASAN | H231: MUYASAROH | I231: BIO_Images/EBTAQ25-03.071.jpg | J231: BMW - As-Sa'idiyyah
A232: 232 | B232: EBTAQ25.03.072 | C232: AHMAD FERI AKBAR | D232: Laki-laki | E232: DEMAK | F232: 42047 | G232: NUR ROCHIM | H232: FARIDHOTUL CHASANAH | I232: BIO_Images/EBTAQ25-03.072.jpg | J232: BMW - As-Sa'idiyyah
A233: 233 | B233: EBTAQ25.03.074 | C233: BILQIS FAIHA RIFDA | D233: Perempuan | E233: DEMAK | F233: 41991 | G233: MUSRIAN | H233: SUYATI | I233: BIO_Images/EBTAQ25-03.074.jpg | J233: BMW - As-Sa'idiyyah
A234: 234 | B234: EBTAQ25.03.075 | C234: FARISYA FINATUL AGUSTINA | D234: Perempuan | E234: DEMAK | F234: 41868 | G234: MUHAMMAD ARIS | H234: NAFISSATUN NAJIKHAH | I234: BIO_Images/EBTAQ25-03.075.jpg | J234: BMW - As-Sa'idiyyah
A235: 235 | B235: EBTAQ25.03.076 | C235: INAYATUR ROHMAH | D235: Perempuan | E235: DEMAK | F235: 41913 | G235: HASAN BISRI | H235: NUR FAIZAH | I235: BIO_Images/EBTAQ25-03.076.jpg | J235: BMW - As-Sa'idiyyah
A236: 236 | B236: EBTAQ25.03.078 | C236: KIRANA 'AROFATUSYALISAH | D236: Perempuan | E236: DEMAK | F236: 41909 | G236: MUAYADI | H236: MUDAYANAH | I236: BIO_Images/EBTAQ25-03.078.jpg | J236: BMW - As-Sa'idiyyah
